<?xml version="1.0"?>
<!-- Revolute-Revolute Manipulator -->
<robot name="orne_gamma" xmlns:xacro="http://ros.org/wiki/xacro"> 
  <!-- Constants for robot dimensions -->
  <xacro:property name="PI" value="3.1415926535897931"/>

  <!-- Import Rviz colors -->
  <xacro:include filename="$(find orne_description)/urdf/material_colors.xacro"/>
  <xacro:include filename="$(find orne_description)/urdf/gamma/orne_gamma.gazebo"/>
  <xacro:include filename="$(find orne_description)/urdf/sensors/hokuyo.urdf.xacro"/>
  <xacro:include filename="$(find orne_description)/urdf/gamma/orne_gamma_caster.urdf.xacro"/>

  <!--Base Footprint-->
  <link name="base_footprint" />

  <joint name="base_joint" type="fixed">
    <origin xyz="0 0 0" />
    <parent link="base_footprint" />
    <child link="base_link" />
  </joint>
  
  <!-- Base Link -->
  <link name="base_link">
    <visual>
      <origin xyz="0.0 0.0 0.0" rpy="0.0 0.0 0.0"/>>
      <geometry>
	    <box size=".485 .43 .15"/>
      </geometry>
    </visual>
    <collision name="collision">
      <origin xyz="0.0 0.0 0.0" rpy="0.0 0.0 0.0"/>>
      <geometry>
	    <box size=".485 .43 .15"/>
      </geometry>
    </collision>
   <inertial>
    <mass value="15" />
    <origin xyz="0 0 0" rpy="0 0 0"/>
    <inertia ixx="0.25925" ixy="0" ixz="0" iyy="0.32216" iyz="0" izz="0.52516" />
    </inertial>
 </link>

  <link name="left_wheel">
    <collision name="collision">
      <origin xyz="0.0 0.0 0.0" rpy="0.0 0.0 0.0"/>
      <geometry>
         <cylinder  length="0.03" radius="0.0725"/>
      </geometry>
    </collision>
    <visual name="visual">
      <origin xyz="0.0 0.0 0.0" rpy="0.0 0.0 0.0"/>
      <geometry>
        <cylinder  length="0.03" radius="0.0725"/>
      </geometry>
    </visual>
    <inertial>
      <mass value="1" />
      <origin xyz="0.0 0.0 0.0" rpy="0.0 0.0 0.0"/>
      <inertia ixx="0.001" ixy="0" ixz="0" iyy="0.002" iyz="0" izz="0.001" />
    </inertial>
  </link>
  
  <joint type="continuous" name="left_wheel_joint">
    <origin xyz="-0.15 0.15 -0.05" rpy="-1.57 0 0"/>
    <child link="left_wheel"></child>
    <parent link="base_link"></parent>
    <axis xyz="0 0 1"/>
    <limit effort="100" velocity="100.0"  lower="-5000" upper="5000" />
    <dynamics damping="0.1"/>
  </joint> 

  <link name="right_wheel">
    <collision name="collision">
      <origin xyz="0.0 0.0 0.0" rpy="0.0 0.0 0.0"/>
      <geometry>
         <cylinder  length="0.03" radius="0.0725"/>
      </geometry>
    </collision>
    <visual name="visual">
      <origin xyz="0.0 0.0 0.0" rpy="0.0 0.0 0.0"/>
      <geometry>
        <cylinder  length="0.03" radius="0.0725"/>
      </geometry>
    </visual>
    <inertial>
      <mass value="1" />
      <origin xyz="0.0 0.0 0.0" rpy="0.0 0.0 0.0"/>
      <inertia ixx="0.001" ixy="0" ixz="0" iyy="0.002" iyz="0" izz="0.001" />
    </inertial>
  </link>
  
  <joint type="continuous" name="right_wheel_joint">
    <origin xyz="-0.15 -0.15 -0.05" rpy="-1.57 0 0"/>
    <child link="right_wheel"></child>
    <parent link="base_link"></parent>
    <axis xyz="0 0 1"/>
    <limit effort="100" velocity="100.0"  lower="-5000" upper="5000" />
    <dynamics damping="0.1"/>
  </joint>

  <xacro:sensor_hokuyo name="hokuyo" parent="base_link" size="0.05 0.05 0.05">
    <origin xyz="0.25 0 0.1" rpy="0 0 0"/>
  </xacro:sensor_hokuyo>

  <xacro:caster sub="0" parent="base_link" transX="0.15" transY="0.0" transZ="-0.075" />

  <transmission name="tran1">
    <type>transmission_interface/SimpleTransmission</type>
    <joint name="left_wheel_joint">
      <hardwareInterface>VelocityJointInterface</hardwareInterface>
    </joint>   
    <actuator name="left_motor">
      <hardwareInterface>VelocityJointInterface</hardwareInterface>
      <mechanicalReduction>1</mechanicalReduction>
    </actuator>
  </transmission>

  <transmission name="tran2">
    <type>transmission_interface/SimpleTransmission</type>
    <joint name="right_wheel_joint">
      <hardwareInterface>VelocityJointInterface</hardwareInterface>
    </joint>  
    <actuator name="right_motor">
      <hardwareInterface>VelocityJointInterface</hardwareInterface>
      <mechanicalReduction>1</mechanicalReduction>
    </actuator>
  </transmission>

  <joint name="camera_joint" type="fixed">
    <origin xyz="0.223 -0.011 0.565" rpy="0 0.124 0"/> 
    <parent link="base_link"/>
    <child link="camera_link"/>
  </joint>

  <link name="camera_link">
    <collision>
      <origin xyz="0.005 0.011 0.013" rpy="0 0 0"/>
      <geometry>
        <box size="0.015 0.030 0.027"/>
      </geometry>
    </collision>
  </link>

  <joint name="camera_rgb_joint" type="fixed">
    <origin xyz="0.003 0.011 0.009" rpy="0 0 0"/>
    <parent link="camera_link"/>
    <child link="camera_rgb_frame"/>
  </joint>
  <link name="camera_rgb_frame"/>

  <joint name="camera_rgb_optical_joint" type="fixed">
    <origin xyz="0 0 0" rpy="-1.57 0 -1.57"/>
    <parent link="camera_rgb_frame"/>
    <child link="camera_rgb_optical_frame"/>
  </joint>
  <link name="camera_rgb_optical_frame"/>

  <joint name="camera_rgb_left_joint" type="fixed">
    <origin xyz="0.003 0.111 0.009" rpy="0 0 0.175"/>
    <parent link="camera_link"/>
    <child link="camera_rgb_left_frame"/>
  </joint>
  <link name="camera_rgb_left_frame"/>

  <joint name="camera_rgb_optical_left_joint" type="fixed">
    <origin xyz="0 0 0" rpy="-1.57 0 -1.57"/>
    <parent link="camera_rgb_left_frame"/>
    <child link="camera_rgb_optical_left_frame"/>
  </joint>
  <link name="camera_rgb_optical_left_frame"/>

  <joint name="camera_rgb_right_joint" type="fixed">
    <origin xyz="0.003 -0.089 0.009" rpy="0 0 -0.175"/>
    <parent link="camera_link"/>
    <child link="camera_rgb_right_frame"/>
  </joint>
  <link name="camera_rgb_right_frame"/>

  <joint name="camera_rgb_optical_right_joint" type="fixed">
    <origin xyz="0 0 0" rpy="-1.57 0 -1.57"/>
    <parent link="camera_rgb_right_frame"/>
    <child link="camera_rgb_optical_right_frame"/>
  </joint>
  <link name="camera_rgb_optical_right_frame"/>

</robot>
