<?xml version="1.0"?>
<!-- Revolute-Revolute Manipulator -->
<robot name="t_frog" xmlns:xacro="http://www.ros.org/wiki/xacro">

  <!-- Constants for robot dimensions -->
  <xacro:property name="PI" value="3.1415926535897931"/>
  <xacro:property name="width" value="0.1" /> <!-- Square dimensions (widthxwidth) of beams -->
  <xacro:property name="height1" value="2" /> <!-- Link 1 -->
  <xacro:property name="height2" value="1" /> <!-- Link 2 -->
  <xacro:property name="height3" value="1" /> <!-- Link 3 -->
  <xacro:property name="camera_link" value="0.05"/> <!-- Size of square 'camera' box -->
  <xacro:property name="hokuyo_link" value="0.1" /> <!-- Size of square 'hokuyo' box -->
  <xacro:property name="axel_offset" value="0.05"/> <!-- Space btw top of beam and the each joint -->

  <!-- Import all Gazebo-customization elements, including Gazebo colors -->
  <xacro:include filename="$(find t_frog_description)/urdf/t_frog.gazebo" />
  <!-- Import Rviz colors -->
  <xacro:include filename="$(find t_frog_description)/urdf/materials.xacro" />

  <!-- Used for fixing robot to Gazebo 'base_link' -->
  <!--
  <link name="world"/>

  <joint name="continuous" type="continuous">
    <parent link="world"/>
    <child link="base_link"/>
  </joint>
  -->

  <!-- Base Link -->
  <link name="base_link">
    <collision>
      <origin xyz="0 0 .1" rpy="0 0 0"/>
      <geometry>
	<box size=".4 .2 .1"/>
      </geometry>
    </collision>

    <visual>
      <origin xyz="0 0 .1" rpy="0 0 0"/>
      <geometry>
	<box size=".4 .2 .1"/>
      </geometry>
      <material name="orange"/>
    </visual>
    
    <collision>
      <origin xyz="-0.15 0 0.03" rpy="0 0 0"/>
      <geometry>
	<sphere radius="0.02"/>
      </geometry>
      <surface>
        <friction>
          <ode>
	    <mu>0</mu>
	    <mu2>0</mu2>
	    <slip1>1.0</slip1>
	    <slip2>1.0</slip2>
	  </ode>
        </friction>
      </surface>
    </collision>
    
    <visual>
      <origin xyz="-0.15 0 0.03" rpy="0 0 0"/>
      <geometry>
	<sphere radius="0.02"/>
      </geometry>
      <material name="orange"/>
    </visual>

    <inertial>
       <mass value="1e-5" />
       <origin xyz="0 0 .1 " rpy="0 0 0"/>
       <inertia ixx="1e-6" ixy="0" ixz="0" iyy="1e-6" iyz="0" izz="1e-6" />
    </inertial>
  </link>

  <link name="left_wheel">
    <collision name="collision">
      <origin xyz="0 0.03 0" rpy="0 1.5707 1.5707"/>
      <geometry>
         <cylinder  length="0.05" radius="0.1"/>
      </geometry>
    </collision>
    <visual name="visual">
      <origin xyz="0 0.03 0" rpy="0 1.5707 1.5707"/>
      <geometry>
        <cylinder  length="0.05" radius="0.1"/>
      </geometry>
    </visual>
    <inertial>
      <mass value="1e-5" />
      <origin xyz="0 0.03 0"/>
      <inertia ixx="1e-6" ixy="0" ixz="0" iyy="1e-6" iyz="0" izz="1e-6" />
    </inertial>
  </link>
  
  <joint type="revolute" name="left_wheel_hinge">
    <origin xyz="0.1 0.13 0.1" rpy="0 0 0"/>
    <child link="left_wheel">left_wheel</child>
    <parent link="base_link">base_link</parent>
    <axis xyz="0 1 0"/>
    <limit effort="30" velocity="1.0"  lower="-100" upper="100" />
  </joint> 
  
  <link name="right_wheel">
    <collision name="collision">
      <origin xyz="0 -0.03 0" rpy="0 1.5707 1.5707"/>
      <geometry>
         <cylinder  length="0.05" radius="0.1"/>
      </geometry>
    </collision>
    <visual name="visual">
      <origin xyz="0 -0.03 0" rpy="0 1.5707 1.5707"/>
      <geometry>
        <cylinder  length="0.05" radius="0.1"/>
      </geometry>
    </visual>
    <inertial>
      <mass value="1e-5" />
      <origin xyz="0 -0.03 0"/>
      <inertia ixx="1e-6" ixy="0" ixz="0" iyy="1e-6" iyz="0" izz="1e-6" />
    </inertial>
  </link>
  
  <joint type="revolute" name="right_wheel_hinge">
    <origin xyz="0.1 -0.13 0.1" rpy="0 0 0"/>
    <child link="right_wheel">right_wheel</child>
    <parent link="base_link">base_link</parent>
    <axis xyz="0 1 0"/>
    <limit effort="30" velocity="1.0"  lower="-100" upper="100" />
  </joint>

  <joint name="hokuyo_joint" type="fixed">
    <axis xyz="0 1 0"/>
    <origin xyz="0 0 0.175" rpy="0 0 0"/>
    <parent link="base_link"/>
    <child link="hokuyo_link"/>
  </joint>

  <link name="hokuyo_link">
    <collision>
      <origin xyz="0 0 0" rpy="0 0 0"/>
      <geometry>
        <box size="${hokuyo_link} ${hokuyo_link} ${hokuyo_link}"/>
      </geometry>
    </collision>

    <visual>
      <origin xyz="0 0 0" rpy="0 0 0"/>
      <geometry>
        <mesh filename="package://t_frog_description/meshes/hokuyo.dae"/>
      </geometry>
    </visual>

    <inertial>
      <mass value="1e-5"/>
      <origin xyz="0 0 0" rpy="0 0 0"/>
      <inertia ixx="1e-6" ixy="0" ixz="0" iyy="1e-6" iyz="0" izz="1e-6"/>
    </inertial>
  </link>

  <joint name="camera_joint" type="fixed">
    <axis xyz="0 1 0" />
    <origin xyz="0.2 0 0.175" rpy="0 0 0"/>
    <parent link="base_link"/>
    <child link="camera_link"/>
  </joint>

  <link name="camera_link">
    <collision>
      <origin xyz="0 0 0" rpy="0 0 0"/>
      <geometry>
        <box size="${camera_link} ${camera_link} ${camera_link}"/>
      </geometry>
    </collision>

    <visual>
      <origin xyz="0 0 0" rpy="0 0 0"/>
      <geometry>
        <box size="${camera_link} ${camera_link} ${camera_link}"/>
      </geometry>
      <material name="red"/>
    </visual>

    <inertial>
      <mass value="1e-5" />
      <origin xyz="0 0 0" rpy="0 0 0"/>
      <inertia ixx="1e-6" ixy="0" ixz="0" iyy="1e-6" iyz="0" izz="1e-6" />
    </inertial>
  </link>
  
  <transmission name="tran1">
    <type>transmission_interface/SimpleTransmission</type>
    <joint name="left_wheel_hinge">
      <hardwareInterface>VelocityJointInterface</hardwareInterface>
    </joint>   
  <actuator name="left_motor">
      <hardwareInterface>VelocityJointInterface</hardwareInterface>
      <mechanicalReduction>1</mechanicalReduction>
    </actuator>
  </transmission>

  <transmission name="tran2">
    <type>transmission_interface/SimpleTransmission</type>
    <joint name="right_wheel_hinge">
      <hardwareInterface>VelocityJointInterface</hardwareInterface>
    </joint>  
  <actuator name="right_motor">
      <hardwareInterface>VelocityJointInterface</hardwareInterface>
      <mechanicalReduction>1</mechanicalReduction>
    </actuator>
  </transmission>
</robot>
